<?xml version="1.0"?>
<robot xmlns:xacro="http://www.ros.org/wiki/xacro">
  <xacro:macro name="load_wheel"
    params="wheel_mass wheel_radius wheel_width use_gazebo prefix side x_reflect y_reflect">
    
    <link name="${side}_wheel_link">
      <visual>
        <origin xyz="0 0 0" rpy="${pi/2} 0 0" />
        <geometry>
          <mesh filename="file://$(find robo_cart_description)/meshes/${side}_wheel.STL" />
        </geometry>
        <material name="dark_gray">
          <color rgba="0.2 0.2 0.2 1.0" />
        </material>
      </visual>
      <collision>
        <origin xyz="0 0 0" rpy="${pi/2} 0 0" />
        <geometry>
          <cylinder radius="${wheel_radius}" length="${wheel_width}" />
        </geometry>
      </collision>
      <inertial>
        <origin xyz="0 0 0" rpy="0 0 0" />
        <mass value="${wheel_mass}" />
        <inertia
          ixx="${(wheel_mass/12.0) * (3*wheel_radius*wheel_radius + wheel_width*wheel_width)}"
          ixy="0" ixz="0" iyy="${(wheel_mass/2.0) * (wheel_radius*wheel_radius)}" iyz="0"
          izz="${(wheel_mass/12.0) * (3*wheel_radius*wheel_radius + wheel_width*wheel_width)}" />
      </inertial>
    </link>
    
    <joint name="${prefix}_${side}_wheel_joint" type="continuous">
      <axis xyz="0 1 0" />
      <parent link="${prefix}_link" />
      <child link="${side}_wheel_link" />
      <origin
        xyz="${(x_reflect * base_length) / 4.0} ${(y_reflect * (base_width + wheel_width)) / 2.0} 0.0"
        rpy="0 0 0" />
    </joint>
    
    <xacro:if value="${use_gazebo}">
      <gazebo reference="${prefix}_${side}_wheel_link">
        <surface>
          <friction>
            <ode>
              <mu>1.0</mu>
              <mu2>0.0</mu2>
            </ode>
          </friction>
        </surface>
        <visual>
          <material>
            <ambient>0.2 0.2 0.2 1.0</ambient>
            <diffuse>0.2 0.2 0.2 1.0</diffuse>
            <specular>0.2 0.2 0.2 1.0</specular>
            <emissive>0.0 0.0 0.0 0.0</emissive>
          </material>
        </visual>
      </gazebo>
    </xacro:if>
  
  </xacro:macro>
</robot>